<?xml version="1.0"?>
<robot name="caster_robot" xmlns:xacro="http://ros.org/wiki/xacro" description="iqr caster robot">
  <xacro:include filename="$(find caster_description)/urdf/common_properties.xacro"/>
  <xacro:include filename="$(find caster_description)/urdf/iqr_caster.gazebo.xacro"/>
  <xacro:property name="M_PI" value="3.1415926535897931" />

  <!-- support_wheel unit -->
  <xacro:macro name="support_wheel" params="parent location *origin">
    <link name="support_wheel_${location}_link">
      <visual>
        <origin xyz="0 0 0" rpy="0 0 0" />
        <geometry>
          <mesh filename="package://caster_description/mesh/support_wheel.stl" />
        </geometry>
        <material name="">
          <color rgba="0.3 0.3 0.3 1.0" />
        </material>
      </visual>

      <collision>
        <geometry>
          <box size="0.0185 0.0185 0.1338"/>
        </geometry>
      </collision>

      <inertial>
        <origin xyz="0 0 0" />
        <mass value="0.163" />
        <inertia ixx="0.304" ixy="0.001" ixz="-0.126" 
                 iyy="1.45" iyz="0.369" 
                 izz="0.110" />
      </inertial>
    </link>

    <joint name="support_wheel_${location}_joint" type="fixed">
      <xacro:insert_block name="origin" />
      <parent link="${parent}" />
      <child link="support_wheel_${location}_link" />
      <!-- <axis xyz="0 0 1" /> -->
    </joint>
  </xacro:macro>

  <!-- drive_wheel unit -->
  <xacro:macro name="drive_wheel" params="parent location invert *origin">
    <link name="drive_wheel_${location}_link">
      <visual>
        <origin xyz="0 0 0" rpy="0 0 ${invert*M_PI}" />
        <geometry>
          <mesh filename="package://caster_description/mesh/drive_wheel.stl" />
        </geometry>
        <material name="">
          <color rgba="0.30 0.30 0.30 1" />
        </material>
      </visual>

      <collision>
        <origin xyz="0 0 0" rpy="${M_PI/2} 0 0" />
        <geometry>
          <cylinder length="0.035" radius="0.075" />
        </geometry>
      </collision>

      <inertial>
        <origin xyz="0 0 0" />
        <mass value="0.803" />
        <inertia ixx="0.0016" ixy="0.0" ixz="-0.0" 
                 iyy="0.003" iyz="0.0" 
                 izz="0.0016" />
      </inertial>
    </link>

    <joint name="drive_wheel_${location}_joint" type="continuous">
      <xacro:insert_block name="origin" />
      <parent link="${parent}" />
      <child link="drive_wheel_${location}_link" />
      <axis xyz="0 1 0" rpy="0 0 0"/>
    </joint>
  </xacro:macro>

  <!-- ULT unit-->
  <xacro:macro name="ultrasonic" params="parent location *origin">
    <link name="ultrasonic_${location}_link">
      <visual>
        <origin xyz="0 0 0" rpy="0 ${M_PI/2} 0" />
        <geometry>
          <cylinder length="0.01" radius="0.01" />
        </geometry>
        <material name="">
          <color rgba="0.3 0.3 0.3 1.0" />
        </material>
      </visual>
<!--       <inertial>
        <origin xyz="0 0 0" />
        <mass value="0.01" />
      </inertial> -->
    </link>

    <joint name="ultrasonic_${location}_joint" type="fixed">
      <xacro:insert_block name="origin" />
      <parent link="${parent}" />
      <child link="ultrasonic_${location}_link" />
    </joint>
  </xacro:macro>

  <!-- base footprint -->
  <link name="base_footprint">
    <origin xyz="0 0 0" rpy="0 0 0" />
  </link>
  <!-- base link -->
  <link name="base_link">
    <visual>
      <origin xyz="0 0 0" rpy="0 0 0" />
      <geometry>
        <mesh filename="package://caster_description/mesh/caster_base.stl" />
      </geometry>
      <material name="">
        <color rgba="0.98 1.0 0.94 1.0" />
      </material>
    </visual>

    <collision>
      <geometry>
         <cylinder length="0.001" radius="0.27"/>
      </geometry>
    </collision>

    <inertial>
      <origin xyz="0 0 0" />
      <mass value="42" />
      <inertia ixx="1.34" ixy="0.016" ixz="0.024" 
               iyy="1.45" iyz="0.006" 
               izz="1.20" />
    </inertial>
  </link>

  <joint name="base_link_joint" type="fixed">
    <origin xyz="0 0 0.03" rpy="0 0 0" />
    <parent link="base_footprint" />
    <child link="base_link" />
  </joint>

  <!-- IMU link -->
  <link name="imu_link" />

  <joint name="imu_link_joint" type="fixed">
    <origin xyz="0 0 0" rpy="0 0 0" />
    <parent link="base_link" />
    <child link="imu_link" />
  </joint>

  <!-- Laser link -->
  <link name="laser_link">
    <inertial>
      <mass value="0.13" />
      <origin xyz="0 0 0" />
      <inertia ixx="0.001" ixy="0.0" ixz="0.0"
               iyy="0.001" iyz="0.0"
               izz="0.001" />
    </inertial>
  </link>
  <joint name="laser_link_joint" type="fixed">
    <origin xyz="0.2301 0 0.147" rpy="0 0 0" />
    <parent link="base_link" />
    <child link="laser_link" />
  </joint>

  <!-- Laser link 2 (rplidar) -->
  <link name="laser_link2" >
    <collision>
      <geometry>
        <cylinder length="0.0315" radius="0.055"/>
      </geometry>
    </collision>
    <inertial>
      <mass value="0.19" />
      <origin xyz="0 0 0" />
      <inertia ixx="0.001" ixy="0.0" ixz="0.0"
               iyy="0.001" iyz="0.0"
               izz="0.001" />
    </inertial>
  </link>
  <joint name="laser_link_joint2" type="fixed">
    <origin xyz="0.01525 0 0.2115" rpy="0 0 ${M_PI}" />
    <parent link="base_link" />
    <child link="laser_link2" />
  </joint>

  <!-- Drive wheel link -->
  <xacro:drive_wheel parent="base_link" invert="0" location="left">
    <origin xyz="0 0.2087 0.045" rpy="0 0 0" />
  </xacro:drive_wheel>
  <xacro:drive_wheel parent="base_link" invert="1" location="right">
    <origin xyz="0 -0.2087 0.045" rpy="0 0 0" />
  </xacro:drive_wheel>

  <!-- Support wheel link -->
  <xacro:support_wheel parent="base_link" location="front_left">
    <origin xyz="0.185 0.150 0.037" rpy="0 0 0" />
  </xacro:support_wheel>
  <xacro:support_wheel parent="base_link" location="front_right">
    <origin xyz="0.185 -0.150 0.037" rpy="0 0 0" />
  </xacro:support_wheel>
  <xacro:support_wheel parent="base_link" location="rear_left">
    <origin xyz="-0.185 0.150 0.037" rpy="0 0 0" />
  </xacro:support_wheel>
  <xacro:support_wheel parent="base_link" location="rear_right">
    <origin xyz="-0.185 -0.150 0.037" rpy="0 0 0" />
  </xacro:support_wheel>

  <!-- Ultrasonic link-->
  <xacro:ultrasonic parent="base_link" location="front_left">
    <origin xyz="0.26248 0.0704 0.0245" rpy="0 0 0.2618" />
  </xacro:ultrasonic>
  <xacro:ultrasonic parent="base_link" location="front_right">
    <origin xyz="0.26248 -0.0704 0.0245" rpy="0 0 -0.2618" />
  </xacro:ultrasonic>
  <xacro:ultrasonic parent="base_link" location="rear_left">
    <origin xyz="-0.26298 0.0704 0.2095" rpy="0 0 2.8798" />
  </xacro:ultrasonic>
  <xacro:ultrasonic parent="base_link" location="rear_right">
    <origin xyz="-0.26298 -0.0704 0.2095" rpy="0 0 -2.8798" />
  </xacro:ultrasonic>
</robot>